Workbook
Name danhsachchonnuocngoai2: OFFSET(nháp!$A$1,MATCH('ĐIỀN THÔNG TIN'!$F$12&"*",DSNUOC,0)-1,0,COUNTIF(DSNUOC,'ĐIỀN THÔNG TIN'!$F$12&"*"),1)
Name DSBANG: OFFSET([1]NHÁP!$Q$2,0,0,COUNTA([1]!Table2[[#All],[BANG]])-1,1)
Name DSBANGTM: OFFSET([1]NHÁP!$Q$2,MATCH([1]ĐIỀN!$B1&"*",DSBANG,0)-1,0,COUNTIF(DSBANG,[1]ĐIỀN!$B1&"*"),1)
Name DSCHON: OFFSET(nháp!$A$1,MATCH('ĐIỀN THÔNG TIN'!$B$2&"*",DSNUOC,0)-1,0,COUNTIF(DSNUOC,'ĐIỀN THÔNG TIN'!$B$2&"*"),1)
Name dschonnuocnuocngoai: OFFSET(nháp!$A$1,MATCH('ĐIỀN THÔNG TIN'!$F$2&"*",DSNUOC,0)-1,0,COUNTIF(DSNUOC,'ĐIỀN THÔNG TIN'!$F$2&"*"),1)
Name DSCHONTIEUBANGNN: OFFSET(nháp!$K$1,MATCH('ĐIỀN THÔNG TIN'!$F$3&"*",DSTIEUBANG,0)-1,0,COUNTIF(DSTIEUBANG,'ĐIỀN THÔNG TIN'!$F$3&"*"),1)
Name DSCHONTIEUBANGVN: OFFSET(nháp!$K$1,MATCH('ĐIỀN THÔNG TIN'!$B$3&"*",DSTIEUBANG,0)-1,0,COUNTIF(DSTIEUBANG,'ĐIỀN THÔNG TIN'!$B$3&"*"),1)
Name DSNUOC: OFFSET([1]NHÁP!$A$2,0,0,COUNTA([1]!Table1[[#All],[DS NƯỚC]])-1,1)
Name DSNUOC: OFFSET([1]NHÁP!$A$2,0,0,COUNTA([1]!Table1[[#All],[DS NƯỚC]])-1,1)
Name DSNUOC: OFFSET(nháp!$A$1,0,0,COUNTA(nháp!$A$1:$A$242),1)
Name DSNUOCTM: OFFSET([1]NHÁP!$A$2,MATCH([1]ĐIỀN!A1&"*",'PHIẾU MSB (nước ngoài)'!DSNUOC,0)-1,0,COUNTIF('PHIẾU MSB (nước ngoài)'!DSNUOC,[1]ĐIỀN!A1&"*"),1)
Name DSNUOCTM: OFFSET([1]NHÁP!$A$2,MATCH([1]ĐIỀN!A1&"*",'PHIẾU MSB (vn)'!DSNUOC,0)-1,0,COUNTIF('PHIẾU MSB (vn)'!DSNUOC,[1]ĐIỀN!A1&"*"),1)
Name DSTIEUBANG: OFFSET(nháp!$K$1,0,0,COUNTA(nháp!$K$1:$K$62),1)
Name dstinh: "OFFSET(Sheet2!$A$1,0,0,COUNTA(Sheet2!$A$1:$A$241),1)"

Sheet PHIẾU ACB (VN)
A6: *Mã số nhận tiền *Money Transfer Control Number | D6: ='ĐIỀN THÔNG TIN'!B1 -> 426-733-0109
A7: *Quốc gia gửi tiền *Country of Origin | D7: ='ĐIỀN THÔNG TIN'!B2 -> MALAYSIA
R8: Thất nghiệp
A9: *Tiểu Bang/ Thành Phố gửi tiền (Đối với các giao dịch gửi từ Mỹ/ Mexico hay Canada) | H9: ='ĐIỀN THÔNG TIN'!B3 -> 0
A10: *City/ State (if sending from USD, Mexico or Canada)
A11: *Loại tiền/ Số tiền nhận *Amount expected to be received | D11: ='ĐIỀN THÔNG TIN'!B4 -> 1044.89 | J11: ='ĐIỀN THÔNG TIN'!C4 -> USD
A12: NGƯỜI NHẬN/ RECEIVER
A13: *Họ và tên *Full name | D13: ='ĐIỀN THÔNG TIN'!B5 -> YEOH JIA JUN
A14: *Ngày sinh (ngày/ tháng/ năm) *Date of birth (dd/mm/yyyy) | D14: ='ĐIỀN THÔNG TIN'!B6 -> 30/08/1996 | H14: *Điện thoại di động/ ĐT cố định *Mobile phone/ Telephone | K14: ='ĐIỀN THÔNG TIN'!B7 -> 0337378229
A15: *Địa chỉ hiện tại *Present Address | D15: ='ĐIỀN THÔNG TIN'!B8 -> 75/9 BINH QUOI THANH DA BINH THANH
A16: *Địa chỉ đăng ký hộ khẩu (Nếu khác thông tin trên, vui lòng cung cấp) | D16: ='ĐIỀN THÔNG TIN'!B9 -> 0
A17: *Permanent Address (if different from above, please provide) | D17: Số/ Number Đường/ Street Quận/ huyện/Town/ District Tỉnh/ thành phố/ Cty/ Province
A18: Thông tin về giấy tờ nhận dạng thức nhất/ Primary ID | D18: *Loại giấy tờ nhận dạng * ID type | G18: ='ĐIỀN THÔNG TIN'!B10 -> CCCD | I18: *Số giấy tờ nhận dạng * ID Number | K18: ='ĐIỀN THÔNG TIN'!B11 -> A60556819
A19: *Quốc gia cấp *Issuing country | C19: ='ĐIỀN THÔNG TIN'!B12 -> MALAYSIA | D19: *Nơi cấp *Place of issue | G19: ='ĐIỀN THÔNG TIN'!B20 -> Cục cảnh sát QLHC về TTXH | I19: *Ngày cấp *Issue date | J19: ='ĐIỀN THÔNG TIN'!B13 -> 19/12/2023 | K19: *Ngày hết hạn *Expiry date | M19: ='ĐIỀN THÔNG TIN'!B14 -> 19/12/2028
A20: Thông tin về giấy tờ nhận dạng thứ hai - Nếu quốc gia cấp của giấy tờ nhận dạng thứ nhất không phải Việt Nam và có yêu cầu thị thực vào Việt Nam. Second ID/ Visa information - if Issuing Country of Primary ID is different from Vietnam wher Visa to Vietnam is required
A21: *Visa type *Issuing country | D21: *Số Visa *Visa Number | I21: *Ngày cấp *Issue date | K21: *Ngày hết hạn *Expiry date
A22: *Tình trạng công việc *Employment Status | D22: ='ĐIỀN THÔNG TIN'!B15 -> Thất nghiệp
A23: *Quốc gia khai sinh *Country of birth | D23: =C19 -> MALAYSIA | H23: *Quốc tịch *Country of citizen | J23: =D23 -> MALAYSIA
A24: *Người gửi và người nhận là (Vui lòng ghi rõ mối quan hệ) The Sender is my (please indicate relationship) | F24: ='ĐIỀN THÔNG TIN'!B16 -> Người thân | H24: *Mục đích giao dịch *Purpose of Transaction | K24: ='ĐIỀN THÔNG TIN'!B17 -> Chi phí đi lại
A26: NGƯỜI GỬI/ SENDER
A27: *Họ và tên *Full name | B27: ='ĐIỀN THÔNG TIN'!B18 -> YEOH JIA JUN
A28: * Câu hỏi kiểm tra (giới hạn 4 từ) | I28: Câu trả lời
A29: * Test question (Limt 4 words) | I29: Answers
A30: Tôi ký xác nhận các nội dung sau (By signing this form, I):
A31: 1, Thể hiện sự đồng ý với việc chuyển giao thông tin cá nhân của tôi trong phần đăng ký ở trên nhằm mục đích để WU và các chi nhánh thành viên tại các quốc gia như Mỹ thực hiện các dịch vụ chuyển tiền cho tôi và thực hiện các hoạt động xử lý theo đúng quy định trong mục Bảo vệ dữ liệu tương ứng các điều kiện. Tôi có quyền rút lại sự đồng ý của tôi bất cứ lúc nào
A32: 1, Expressly consent to the transfer of my personal data entered above to WU and its affiliates located in countries such as U.S. for the purposes of providing the money transfer service to me and undertaking the additional data processing activities specified in the Data Protection section of the terms and conditions. I have the right to withdraw my consent at any time
A33: 2, Thể hiện sự đồng ý cho việc thực hiện các hoạt động lưu trữ và thông tin tiếp thị 2, Expressly consent to the carrying out of profiling activities and marketing communications | I33: Ngày Date | J33: =TODAY() -> 45846 | K33: Chữ ký khách hàng (Ký và ghi rõ họ tên) Customer Signature
A34: 3, Xác nhận thông tin tôi cung cấp là chính xác và tôi đã đọc và chấp nhận các điều khoản và điều kiện của dịch vụ ở trang sau 3, Confirm that the information I have provided is correct and I have read and accepted the terms and conditions of the service overleaf
A35: PHẦN DÀNH CHO ĐẠI LÝ ĐIỀN/ PLEASE DO NOT WRITE BELOW
A36: GIAO DỊCH VIÊN ĐIỀN/ OFFICE USE ONLY | F36: THÔNG TIN NHẬN DẠNG/ IDENTIFICATION
A37: Mã số chuyển tiền MTCN | C37: =D6 -> 426-733-0109 | F37: Số Giấy tờ nhận dạng ID Number | H37: =K18 -> A60556819 | J37: Tỉ giá quy đổi áp dụng cho việc chuyển tiền ghi ở trên. Hầu hết số tiền chuyển đều được quy đổi sang đồng tiền thanh toán vào thời điểm số tiền này được gửi. Tuy nhiên, tại một số nước, pháp luật sở tại quy định số tiền chuyển chỉ được quy đổi khi tiền được chi trả. Nếu quý khách gửi tiền đến một trong những nước này, tỉ giá quy đổi ghi trên chỉ là ước tính, và tỉ giá quy đổi thực sẽ được xác định vào thời điểm chi trả. Nếu quý khách có thắc mắc về tỉ giá quy đổi được áp dụng cho việc chuyển tiền,vui lòng hỏi Đại lý. MỘT SỐ ĐIỀU KHOẢN VÀ ĐIỀU KIỆN ĐIỀU CHỈNH DỊCH VỤ CHUYỂN TIỀN MÀ BẠN ĐÃ CHỌN ĐÃ ĐƯỢC QUY ĐỊNH Ở MẶT SAU CỦA PHIẾU NÀY. KHI KÝ TÊN VÀO PHIẾU NÀY, QUÝ KHÁCH CHẤP NHẬN CÁC ĐIỀU KHOẢN VÀ ĐIỀU KIỆN ĐÓ. BÊN CẠNH CHI PHÍ CHUYỂN TIỀN,WESTERN UNION VÀ ĐẠI LÝ WESTERN UNION CÒN CÓ THÊM LỢI NHUẬN TỪ VIỆC ĐỔI TIỀN. XIN VUI LÒNG XEM CÁC THÔNG TIN QUAN TRONG LIÊN QUAN ĐẾN VIỆC ĐỔI TIỀNĐƯỢC QUY ĐỊNH Ở MẶT SAU CỦA PHIẾU NÀY. QUY KHÁCH NÊN TỰ BÁO VỆ MÌNH TRÁNH KHÔNG BỊ LỪA GẠT. HÃY CẨN THẬN KHI CÓ NGƯỜI LẠ YÊU CẦU QUY KHÁCH CHUYỂN TIỀN, The exchange rate applicable to your transfer appears above. Most money transfers are converted into the payment currency at the time they are sent. However, in a few countries, local regulations require money transfer to be converted only when they are paid. If you are sending to one of those countries, the exchange rate noted above is only an estimate, and the actual exchange rate will be determined at the time of payment. Ask the Agent if you have questions about the exchange rate applicable to your transfer. CERTAIN TERMS AND CONDITIONS GOVERNING THE MONEY TRANSFER SERVICE YOU HAVE SELECTED ARE SET FORTH ON THE BACK OF THIS FORM. BY SIGNING THIS FORM, YOU ARE AGREEING TO THOSE TERMS AND CONDITIONS. IN ADDITION TO THE TRANSFER FEE, WESTERN UNION AND ITS AGENTS ALSO MAKE MONEY FROM THE EXCHANGE OF CURRENCIES. PLEASE SEE THE IMPORTANT INFORMATION REGARDING THE CURRENCY AND OTHER LEGAL RESTRICTIONS THAT MAY DELAY THE TRANSACTIONS SET FORM ON THE BACK OF THIS FORM. PROTECT YOURSELF FROM CONSUMER FRAUD. BE CAREFUL WHEN A STRANGER ASKS YOU TO SEND MONEY.
A39: Số tiền chuyển Principle Amount | C39: =D11 -> 1044.89 | D39: =J11 -> USD | F39: Loại Giấy tờ nhận dạng ID Type | H39: =G18 -> CCCD
A41: Phí chuyển tiền Transfer fee | F41: Cơ quan cấp Issuer | H41: ='ĐIỀN THÔNG TIN'!B20 -> Cục cảnh sát QLHC về TTXH
A43: Tổng số tiền Total Amount Received | F43: Ngày phát hành ID Issuing date | G43: =J19 -> 19/12/2023 | H43: Ngày hết hạn ID Expiry date | I43: =M19 -> 19/12/2028
A44: Tỉ giá Exchange Rate | F44: Mã số OPR ID Operator number/ID | G44: 114 | H44: Ngày Date | I44: =TODAY() -> 45846
F45: Nhân viên giao dịch ký tên Agent signature | H45: Giờ Time

Sheet PHIẾU ACB (NƯỚC NGOÀI)
A6: *Mã số nhận tiền *Money Transfer Control Number | D6: ='ĐIỀN THÔNG TIN'!F1 -> 275-145-4064
A7: *Quốc gia gửi tiền *Country of Origin | D7: ='ĐIỀN THÔNG TIN'!F2 -> AUSTRALIA
R8: Thất nghiệp
A9: *Tiểu Bang/ Thành Phố gửi tiền (Đối với các giao dịch gửi từ Mỹ/ Mexico hay Canada)
A10: *City/ State (if sending from USD, Mexico or Canada) | H10: ='ĐIỀN THÔNG TIN'!F3 -> 0
A11: *Loại tiền/ Số tiền nhận *Amount expected to be received | D11: ='ĐIỀN THÔNG TIN'!F4 -> 156.98 | M11: ='ĐIỀN THÔNG TIN'!G4 -> USD
A12: NGƯỜI NHẬN/ RECEIVER
A13: *Họ và tên *Full name | C13: ='ĐIỀN THÔNG TIN'!F5 -> ALEX ROBERTS
A14: *Ngày sinh (ngày/ tháng/ năm) *Date of birth (dd/mm/yyyy) | D14: ='ĐIỀN THÔNG TIN'!F6 -> 21/06/1983 | H14: *Điện thoại di động/ ĐT cố định *Mobile phone/ Telephone | K14: ='ĐIỀN THÔNG TIN'!F7 -> 0783269349
A15: *Địa chỉ hiện tại *Present Address | D15: ='ĐIỀN THÔNG TIN'!F8 -> 97DUONG 66 P THAO DIEN Q2
A16: *Địa chỉ đăng ký hộ khẩu (Nếu khác thông tin trên, vui lòng cung cấp) | D16: ='ĐIỀN THÔNG TIN'!F9 -> 0
A17: *Permanent Address (if different from above, please provide)
A18: Thông tin về giấy tờ nhận dạng thức nhất/ Primary ID | D18: *Loại giấy tờ nhận dạng * ID type | G18: ='ĐIỀN THÔNG TIN'!F10 -> PASSPORT | I18: *Số giấy tờ nhận dạng * ID Number | K18: ='ĐIỀN THÔNG TIN'!F11 -> 146171983
A19: *Quốc gia cấp *Issuing country | C19: ='ĐIỀN THÔNG TIN'!F12 -> UNITED KINGDOM | D19: *Nơi cấp *Place of issue | I19: *Ngày cấp *Issue date | J19: ='ĐIỀN THÔNG TIN'!F13 -> 11/04/2024 | K19: *Ngày hết hạn *Expiry date | M19: ='ĐIỀN THÔNG TIN'!F14 -> 11/04/2034
A20: Thông tin về giấy tờ nhận dạng thứ hai - Nếu quốc gia cấp của giấy tờ nhận dạng thứ nhất không phải Việt Nam và có yêu cầu thị thực vào Việt Nam. Second ID/ Visa information - if Issuing Country of Primary ID is different from Vietnam wher Visa to Vietnam is required
A21: *Visa type *Issuing country | C21: ='ĐIỀN THÔNG TIN'!F15 -> Du lịch / Tourists | D21: *Số Visa *Visa Number | G21: ='ĐIỀN THÔNG TIN'!F16 -> F-146171983 | I21: *Ngày cấp *Issue date | J21: ='ĐIỀN THÔNG TIN'!F17 -> 17/05/2025 | K21: *Ngày hết hạn *Expiry date | M21: ='ĐIỀN THÔNG TIN'!F18 -> 30/06/2025
A22: *Tình trạng công việc *Employment Status | D22: ='ĐIỀN THÔNG TIN'!F19 -> Nghề tự do / Freelancer | H22: *Tên công ty *Employer Name
A23: *Loại hình công việc hoặc Tên trường học (nếu là Sinh viên/ Học sinh) *Employment Industry/ School name (If Student is selected)
A24: *Quốc gia khai sinh *Country of birth | D24: ='ĐIỀN THÔNG TIN'!F20 -> UNITED KINGDOM | H24: *Quốc tịch *Country of citizen | J24: =C19 -> UNITED KINGDOM
A25: *Người gửi và người nhận là (Vui lòng ghi rõ mối quan hệ) The Sender is my (please indicate relationship) | F25: ='ĐIỀN THÔNG TIN'!F21 -> Gia đình (FAMILY) | H25: *Mục đích giao dịch *Purpose of Transaction | K25: ='ĐIỀN THÔNG TIN'!F22 -> Chi phí đi lại (TRAVEL EXPENSE)
A27: NGƯỜI GỬI/ SENDER
A28: *Họ và tên *Full name | B28: ='ĐIỀN THÔNG TIN'!F23 -> JAY ROBERTS
A29: Tôi ký xác nhận các nội dung sau (By signing this form, I):
A30: 1, Thể hiện sự đồng ý với việc chuyển giao thông tin cá nhân của tôi trong phần đăng ký ở trên nhằm mục đích để WU và các chi nhánh thành viên tại các quốc gia như Mỹ thực hiện các dịch vụ chuyển tiền cho tôi và thực hiện các hoạt động xử lý theo đúng quy định trong mục Bảo vệ dữ liệu tương ứng các điều kiện. Tôi có quyền rút lại sự đồng ý của tôi bất cứ lúc nào
A31: 1, Expressly consent to the transfer of my personal data entered above to WU and its affiliates located in countries such as U.S. for the purposes of providing the money transfer service to me and undertaking the additional data processing activities specified in the Data Protection section of the terms and conditions. I have the right to withdraw my consent at any time
I32: Ngày Date | J32: =TODAY() -> 45846 | K32: Chữ ký khách hàng (Ký và ghi rõ họ tên) Customer Signature
A33: 3, Xác nhận thông tin tôi cung cấp là chính xác và tôi đã đọc và chấp nhận các điều khoản và điều kiện của dịch vụ ở trang sau 3, Confirm that the information I have provided is correct and I have read and accepted the terms and conditions of the service overleaf
A34: PHẦN DÀNH CHO ĐẠI LÝ ĐIỀN/ PLEASE DO NOT WRITE BELOW
A35: GIAO DỊCH VIÊN ĐIỀN/ OFFICE USE ONLY | F35: THÔNG TIN NHẬN DẠNG/ IDENTIFICATION
A36: Mã số chuyển tiền MTCN | C36: =D6 -> 275-145-4064 | F36: Số Giấy tờ nhận dạng ID Number | H36: =K18 -> 146171983 | J36: Tỉ giá quy đổi áp dụng cho việc chuyển tiền ghi ở trên. Hầu hết số tiền chuyển đều được quy đổi sang đồng tiền thanh toán vào thời điểm số tiền này được gửi. Tuy nhiên, tại một số nước, pháp luật sở tại quy định số tiền chuyển chỉ được quy đổi khi tiền được chi trả. Nếu quý khách gửi tiền đến một trong những nước này, tỉ giá quy đổi ghi trên chỉ là ước tính, và tỉ giá quy đổi thực sẽ được xác định vào thời điểm chi trả. Nếu quý khách có thắc mắc về tỉ giá quy đổi được áp dụng cho việc chuyển tiền,vui lòng hỏi Đại lý. MỘT SỐ ĐIỀU KHOẢN VÀ ĐIỀU KIỆN ĐIỀU CHỈNH DỊCH VỤ CHUYỂN TIỀN MÀ BẠN ĐÃ CHỌN ĐÃ ĐƯỢC QUY ĐỊNH Ở MẶT SAU CỦA PHIẾU NÀY. KHI KÝ TÊN VÀO PHIẾU NÀY, QUÝ KHÁCH CHẤP NHẬN CÁC ĐIỀU KHOẢN VÀ ĐIỀU KIỆN ĐÓ. BÊN CẠNH CHI PHÍ CHUYỂN TIỀN,WESTERN UNION VÀ ĐẠI LÝ WESTERN UNION CÒN CÓ THÊM LỢI NHUẬN TỪ VIỆC ĐỔI TIỀN. XIN VUI LÒNG XEM CÁC THÔNG TIN QUAN TRONG LIÊN QUAN ĐẾN VIỆC ĐỔI TIỀNĐƯỢC QUY ĐỊNH Ở MẶT SAU CỦA PHIẾU NÀY. QUY KHÁCH NÊN TỰ BÁO VỆ MÌNH TRÁNH KHÔNG BỊ LỪA GẠT. HÃY CẨN THẬN KHI CÓ NGƯỜI LẠ YÊU CẦU QUY KHÁCH CHUYỂN TIỀN, The exchange rate applicable to your transfer appears above. Most money transfers are converted into the payment currency at the time they are sent. However, in a few countries, local regulations require money transfer to be converted only when they are paid. If you are sending to one of those countries, the exchange rate noted above is only an estimate, and the actual exchange rate will be determined at the time of payment. Ask the Agent if you have questions about the exchange rate applicable to your transfer. CERTAIN TERMS AND CONDITIONS GOVERNING THE MONEY TRANSFER SERVICE YOU HAVE SELECTED ARE SET FORTH ON THE BACK OF THIS FORM. BY SIGNING THIS FORM, YOU ARE AGREEING TO THOSE TERMS AND CONDITIONS. IN ADDITION TO THE TRANSFER FEE, WESTERN UNION AND ITS AGENTS ALSO MAKE MONEY FROM THE EXCHANGE OF CURRENCIES. PLEASE SEE THE IMPORTANT INFORMATION REGARDING THE CURRENCY AND OTHER LEGAL RESTRICTIONS THAT MAY DELAY THE TRANSACTIONS SET FORM ON THE BACK OF THIS FORM. PROTECT YOURSELF FROM CONSUMER FRAUD. BE CAREFUL WHEN A STRANGER ASKS YOU TO SEND MONEY.
A38: Số tiền chuyển Principle Amount | C38: =D11 -> 156.98 | F38: Loại Giấy tờ nhận dạng ID Type | H38: =G18 -> PASSPORT
A40: Phí chuyển tiền Transfer fee | F40: Cơ quan cấp Issuer | H40: =C19 -> UNITED KINGDOM
A42: Tổng số tiền Total Amount Received | F42: Ngày phát hành ID Issuing date | G42: =J19 -> 11/04/2024 | H42: Ngày hết hạn ID Expiry date | I42: =M19 -> 11/04/2034
A43: Tỉ giá Exchange Rate | F43: Mã số OPR ID Operator number/ID | H43: Ngày Date | I43: =TODAY() -> 45846
F45: Nhân viên giao dịch ký tên Agent signature | H45: Giờ Time

Sheet ĐIỀN THÔNG TIN
A1: MTCN | B1: 426-733-0109 | D1: NGƯỜI NƯỚC NGOÀI | E1: MTCN | F1: 275-145-4064
A2: Nước gửi tiền | B2: MALAYSIA | E2: Nước gửi tiền | F2: AUSTRALIA
A3: Tiểu bang (usa, can, mex) | E3: Tiểu bang (usa, can, mex)
A4: Số tiền nhận/Loại tiền | B4: 1044.89 | C4: =IF(B4<100000,"USD","VND") -> USD | E4: Số tiền nhận | F4: 156.98 | G4: =IF(F4<10000,"USD","VND") -> USD
A5: Tên ngươi nhận | B5: YEOH JIA JUN | E5: Tên ngươi nhận | F5: ALEX ROBERTS
A6: Ngày sinh | B6: 30/08/1996 | E6: Ngày sinh | F6: 21/06/1983
A7: SDT | B7: 0337378229 | E7: SDT | F7: 0783269349
A8: Địa chỉ hiện tại | B8: 75/9 BINH QUOI THANH DA BINH THANH | E8: Địa chỉ hiện tại | F8: 97DUONG 66 P THAO DIEN Q2
A9: Địa chỉ CCCD | E9: Địa chỉ CCCD
A10: Loại giấy tờ tùy thân | B10: CCCD | E10: Loại giấy tờ tùy thân | F10: PASSPORT
A11: Số giấy tờ tùy thân | B11: A60556819 | E11: Số Passport | F11: 146171983
A12: Quốc gia cấp | B12: MALAYSIA | E12: Quốc gia cấp | F12: UNITED KINGDOM
A13: Ngày cấp | B13: 19/12/2023 | E13: Ngày cấp | F13: 11/04/2024
A14: Ngày hết hạn | B14: 19/12/2028 | E14: Ngày hết hạn | F14: 11/04/2034
A15: Tình trạng việc làm | B15: Thất nghiệp | E15: Loại Visa | F15: Du lịch / Tourists
A16: Quan hệ | B16: Người thân | E16: Số visa | F16: F-146171983
A17: Mục đích nhận tiền | B17: Chi phí đi lại | E17: Ngày cấp visa | F17: 17/05/2025
A18: Tên người gửi | B18: YEOH JIA JUN | E18: Ngày hết hạn visa | F18: 30/06/2025
A19: Ngày nhận tiên | B19: KHONG DIEN | E19: Tình trạng việc làm | F19: Nghề tự do / Freelancer
A20: Cơ quan cấp | B20: =IF(B10="CCCD","Cục cảnh sát QLHC về TTXH",IF(B10="CMND","Công an tỉnh",IF(B10="PASSPORT","Cục quản lý xuất nhập cảnh",))) -> Cục cảnh sát QLHC về TTXH | E20: Quốc gia khai sinh | F20: UNITED KINGDOM
E21: Quan hệ | F21: Gia đình (FAMILY)
E22: Mục đích nhận tiền | F22: Chi phí đi lại (TRAVEL EXPENSE)
B23: chọn lựa thông số | E23: Tên người gửi | F23: JAY ROBERTS
B24: tự điền | E24: Ngày nhận tiên | F24: 20-06-2025
B25: tự điền

Sheet MẪU CHI DÙM
A1: VIỆT NAM | J1: NƯỚC NGOÀI
A2: MTCN: | C2: ='ĐIỀN THÔNG TIN'!B1 -> 426-733-0109 | J2: MTCN: | L2: ='ĐIỀN THÔNG TIN'!F1 -> 275-145-4064
A3: Họ và tên: | C3: ='ĐIỀN THÔNG TIN'!B5 -> YEOH JIA JUN | J3: Họ và tên: | L3: ='ĐIỀN THÔNG TIN'!F5 -> ALEX ROBERTS
A4: Số tiền: | G4: TỰ ĐIỀN | J4: Số tiền: | P4: TỰ ĐIỀN
A5: ——————————- | J5: ——————————-
A6: Địa chỉ: | C6: ='ĐIỀN THÔNG TIN'!B8 -> 75/9 BINH QUOI THANH DA BINH THANH | J6: Địa chỉ: | L6: ='ĐIỀN THÔNG TIN'!F8 -> 97DUONG 66 P THAO DIEN Q2
A7: Địa chỉ 2 (nếu có): | C7: ='ĐIỀN THÔNG TIN'!B9 -> 0 | J7: Địa chỉ 2 (nếu có): | L7: ='ĐIỀN THÔNG TIN'!F9 -> 0
A8: Số điện thoại: | C8: ='ĐIỀN THÔNG TIN'!B7 -> 0337378229 | J8: Số điện thoại: | L8: ='ĐIỀN THÔNG TIN'!F7 -> 0783269349
A9: ——————————- | J9: ——————————-
A10: CCCD/Hộ chiếu: | C10: ='ĐIỀN THÔNG TIN'!B11 -> A60556819 | J10: CCCD/Hộ chiếu: | L10: ='ĐIỀN THÔNG TIN'!F11 -> 146171983
A11: Ngày hết hạn: | C11: ='ĐIỀN THÔNG TIN'!B14 -> 19/12/2028 | J11: Ngày hết hạn: | L11: ='ĐIỀN THÔNG TIN'!F14 -> 11/04/2034
A12: Ngày cấp: | C12: ='ĐIỀN THÔNG TIN'!B13 -> 19/12/2023 | J12: Ngày cấp: | L12: ='ĐIỀN THÔNG TIN'!F13 -> 11/04/2024
A13: Ngày sinh: | C13: ='ĐIỀN THÔNG TIN'!B6 -> 30/08/1996 | J13: Ngày sinh: | L13: ='ĐIỀN THÔNG TIN'!F6 -> 21/06/1983
A14: ——————————- | J14: ——————————-
A15: Nghề nghiệp: | C15: ='ĐIỀN THÔNG TIN'!B15 -> Thất nghiệp | J15: Nghề nghiệp: | L15: ='ĐIỀN THÔNG TIN'!F19 -> Nghề tự do / Freelancer
A16: Mục đích giao dịch: | C16: ='ĐIỀN THÔNG TIN'!B17 -> Chi phí đi lại | J16: Mục đích giao dịch: | L16: ='ĐIỀN THÔNG TIN'!F22 -> Chi phí đi lại (TRAVEL EXPENSE)
A17: —————————— | J17: ——————————
A18: Số VISA (Nếu có): | J18: Số VISA (Nếu có): | L18: ='ĐIỀN THÔNG TIN'!F16 -> F-146171983
A19: Ngày hết hạn: | J19: Ngày hết hạn: | L19: ='ĐIỀN THÔNG TIN'!F18 -> 30/06/2025
A20: Ngày cấp: | J20: Ngày cấp: | L20: ='ĐIỀN THÔNG TIN'!F17 -> 17/05/2025

Sheet PHIẾU MSB (vn)
A6: PHIẾU NHẬN TIỀN- TO RECEIVE MONEY
A8: (Sử dụng cho Đại lý chi trả ngoại tệ của MSB, Áp dụng cho các ĐTKH không yêu cầu sử dụng mẫu của ĐTKH)
A9: * Tên Đối tác Kiều hối
A10: *Mã Số Nhận Tiền | D10: ='ĐIỀN THÔNG TIN'!B1 -> 426-733-0109
A11: *Money Transfer Control Number
A12: * Tên người gửi tiền | D12: ='ĐIỀN THÔNG TIN'!B18 -> YEOH JIA JUN
A13: * Full Name of Sender
A14: *Quốc Gia Gửi Tiền | D14: ='ĐIỀN THÔNG TIN'!B2 -> MALAYSIA
A15: *Country Of Origin
A16: *Tiểu Bang/Thành Phố Gửi Tiền (Đối Với Các Giao Dịch Gửi Đi từ Mỹ, Mexico hoặc Canada) | G16: ='ĐIỀN THÔNG TIN'!B3 -> 0
A17: *Expected Payout City/State (If Sending To USA, Mexico Or Canada)
A18: *Loại Tiền/Số Tiền Nhận | D18: =[1]ĐIỀN!B5 -> 128.3 | I18: ='ĐIỀN THÔNG TIN'!C4 -> USD
A19: *Amount Expected To Be Received
A20: NGƯỜI NHẬN/RECEIVER
A21: *Họ và tên: | D21: ='ĐIỀN THÔNG TIN'!B5 -> YEOH JIA JUN
A22: *Full Name
A23: *Ngày sinh (ngày/tháng/năm): | C23: ='ĐIỀN THÔNG TIN'!B6 -> 30/08/1996 | E23: *Điện thoại di động/ĐT cố định: | G23: ='ĐIỀN THÔNG TIN'!B7 -> 0337378229
A24: *Date of birth (dd/mm/yyyy) | E24: *Mobile phone/Telephone
A25: *Địa chỉ hiện tại | D25: ='ĐIỀN THÔNG TIN'!B8 -> 75/9 BINH QUOI THANH DA BINH THANH
A26: *Present Address
A27: *Địa chỉ đăng ký thường trú (Nếu khác thông tin trên vui lòng cung cấp) | F27: ='ĐIỀN THÔNG TIN'!B9 -> 0
A28: *Permanent Address (if different from adove, please provide)
A29: *Loại giấy tờ nhận dạng: | C29: CCCD | E29: *Số giấy tờ nhận dạng: | G29: ='ĐIỀN THÔNG TIN'!B11 -> A60556819
A30: *ID type | E30: *ID Number
A31: *Ngày cấp | C31: ='ĐIỀN THÔNG TIN'!B13 -> 19/12/2023 | E31: *Ngày hết hạn: | G31: ='ĐIỀN THÔNG TIN'!B14 -> 19/12/2028
A32: *Issue date | E32: *Expiry date
A33: *Quốc gia cấp: | C33: VIET NAM | E33: *Nơi cấp: | G33: Cục cảnh sát QLHC về TTXH
A34: *Issuing Country | E34: *Place of issue
A35: *Quốc gia khai sinh: | C35: VIET NAM | E35: *Quốc tịch: | G35: =[1]ĐIỀN!B19 -> VIET NAM
A36: *Country of birth | E36: *Country of citizen
A39: PHẦN DÀNH CHO KHÁCH HÀNG (Ký, ghi họ tên và xác nhận đã nhận đủ tiền) | F39: PHẦN DÀNH CHO ĐẠI LÝ CHI TRẢ NGOẠI TỆ
A41: Người nhận tiền | F41: Ngày hiệu lực: | H41: Giờ:
F43: Giao dịch viên | H43: Kiểm soát viên

Sheet PHIẾU MSB (nước ngoài)
A6: PHIẾU NHẬN TIỀN- TO RECEIVE MONEY
A8: (Sử dụng cho Đại lý chi trả ngoại tệ của MSB, Áp dụng cho các ĐTKH không yêu cầu sử dụng mẫu của ĐTKH)
A9: * Tên Đối tác Kiều hối
A10: *Mã Số Nhận Tiền | D10: ='ĐIỀN THÔNG TIN'!F1 -> 275-145-4064
A11: *Money Transfer Control Number
A12: * Tên người gửi tiền | D12: ='ĐIỀN THÔNG TIN'!F23 -> JAY ROBERTS
A13: * Full Name of Sender
A14: *Quốc Gia Gửi Tiền | D14: ='ĐIỀN THÔNG TIN'!F2 -> AUSTRALIA
A15: *Country Of Origin
A16: *Tiểu Bang/Thành Phố Gửi Tiền (Đối Với Các Giao Dịch Gửi Đi từ Mỹ, Mexico hoặc Canada) | G16: ='ĐIỀN THÔNG TIN'!F3 -> 0
A17: *Expected Payout City/State (If Sending To USA, Mexico Or Canada)
A18: *Loại Tiền/Số Tiền Nhận | D18: ='ĐIỀN THÔNG TIN'!F4 -> 156.98 | I18: ='ĐIỀN THÔNG TIN'!G4 -> USD
A19: *Amount Expected To Be Received
A20: NGƯỜI NHẬN/RECEIVER
A21: *Họ và tên: | D21: ='ĐIỀN THÔNG TIN'!F5 -> ALEX ROBERTS
A22: *Full Name
A23: *Ngày sinh (ngày/tháng/năm): | C23: ='ĐIỀN THÔNG TIN'!F6 -> 21/06/1983 | E23: *Điện thoại di động/ĐT cố định: | G23: ='ĐIỀN THÔNG TIN'!F7 -> 0783269349
A24: *Date of birth (dd/mm/yyyy) | E24: *Mobile phone/Telephone
A25: *Địa chỉ hiện tại | D25: ='ĐIỀN THÔNG TIN'!F8 -> 97DUONG 66 P THAO DIEN Q2
A26: *Present Address
A27: *Địa chỉ đăng ký thường trú (Nếu khác thông tin trên vui lòng cung cấp) | F27: ='ĐIỀN THÔNG TIN'!F9 -> 0
A28: *Permanent Address (if different from adove, please provide)
A29: *Loại giấy tờ nhận dạng: | C29: PASSPORT | E29: *Số giấy tờ nhận dạng: | G29: ='ĐIỀN THÔNG TIN'!F11 -> 146171983
A30: *ID type | E30: *ID Number
A31: *Ngày cấp | C31: ='ĐIỀN THÔNG TIN'!F13 -> 11/04/2024 | E31: *Ngày hết hạn: | G31: ='ĐIỀN THÔNG TIN'!F18 -> 30/06/2025
A32: *Issue date | E32: *Expiry date
A33: *Quốc gia cấp: | C33: ='ĐIỀN THÔNG TIN'!F12 -> UNITED KINGDOM | E33: *Nơi cấp: | G33: =C33 -> UNITED KINGDOM
A34: *Issuing Country | E34: *Place of issue
A35: *Quốc gia khai sinh: | C35: ='ĐIỀN THÔNG TIN'!F20 -> UNITED KINGDOM | E35: *Quốc tịch: | G35: =C33 -> UNITED KINGDOM
A36: *Country of birth | E36: *Country of citizen
A39: PHẦN DÀNH CHO KHÁCH HÀNG (Ký, ghi họ tên và xác nhận đã nhận đủ tiền) | F39: PHẦN DÀNH CHO ĐẠI LÝ CHI TRẢ NGOẠI TỆ
A41: Người nhận tiền | F41: Ngày hiệu lực: | H41: Giờ:
F43: Giao dịch viên | H43: Kiểm soát viên

Sheet nháp
A1: USA | K1: CA California
A2: AUSTRIA | D2: USD | F2: Buôn bán nhỏ/ Small business | K2: Florida (FL)
A3: AUSTRALIA | D3: VND | F3: Công nghệ thông tin/ Information technology | K3: Texas (TX)
A4: CAMBODIA | F4: Dịch vụ du lịch/ tourists | K4: Hawaii (HI)
A5: CANADA | F5: Dịch vụ làm đẹp/ beauty | I5: Du lịch / Tourists | K5: New Jersey (NJ)
A6: CHINA | F6: Giáo dục / education | I6: Lao động / work permit | K6: Arizona (AZ) | L6: =OFFSET($K$1,MATCH('ĐIỀN THÔNG TIN'!$B$3&"*",DSTIEUBANG,0)-1,0,COUNTIF(DSTIEUBANG,'ĐIỀN THÔNG TIN'!$B$3&"*"),1) -> Arizona (AZ)
A7: CZECH REPUBLIC | F7: Kinh doanh/ business | I7: Thẻ tạm trú | K7: Pennsylvania (PA)
A8: DENMARK | F8: Kỹ sư/ engineer | K8: Bắc Carolina (NC)
A9: FINLAND | F9: Lao động phổ thông/ general labor | K9: Georgia (GA)
A10: FRANCE | F10: Nghề tự do / Freelancer | K10: Colorado (CO)
A11: HONG KONG | F11: Nghỉ Hưu/ retired | K11: Michigan (MI)
A12: INDIA | F12: Nhân viên VP/ office staff | I12: CMND | K12: Massachusetts (MA)
A13: INDONESIA | F13: Nhân viên y tế/ Healthcare | I13: CCCD | K13: Virginia (VA)
A14: JAPAN | F14: Nội trợ/ Housewife | I14: PASSPORT | K14: Illinois (IL)
A15: PHILIPPINES | F15: Sinh Viên/ student | K15: Ohio (OH)
A16: SINGAPORE | F16: Tài xế/ driver | K16: Alaska (AK)
A17: AFGHANISTAN | F17: Thất nghiệp / unemployed | K17: Alabama (AL)
A18: ÅLAND ISLANDS | F18: Xây dựng/ Construction | I18: Chi phí hỗ trợ nhà ở/ gia đình (FAMILY SUPPORT) | K18: New York (NY)
A19: ALBANIA | F19: Phục vụ tôn giáo/ religious | I19: Chi phí đi lại (TRAVEL EXPENSE) | K19: Washington (WA)
A20: ALGERIA | I20: Quà tặng (GIFT) | K20: Tennessee (TN)
A21: AMERICAN SAMOA | K21: Minnesota (MN)
A22: ANDORRA | K22: Maryland
A23: ANGOLA | I23: Anh em (BROTHER) | K23: Oregon (OR)
A24: ANGUILLA | I24: Bạn bè (FRIENDS | K24: South Carolina (SC)
A25: ANTARCTICA | I25: Cha/mẹ (FATHER/MOTHER) | K25: Wisconsin (WI)
A26: ANTIGUA AND BARBUDA | I26: Chị em (SISTER) | K26: Missouri (MO)
A27: ARGENTINA | I27: Chồng (HUSBAND) | K27: Utah (UT)
A28: ARMENIA | I28: Con/cháu (CHILD) | K28: Indiana (IN)
A29: ARUBA | I29: Gia đình (FAMILY) | K29: Louisiana (LA)
A30: AUSTRALIA | I30: Người thân (RELATIVE) | K30: Connecticut (CT)
A31: AZERBAIJAN | I31: Ông bà (GRAND PARENTS) | K31: Kentucky (KY)
A32: BAHAMAS | I32: Vợ / WIFE | K32: Oklahoma (OK)
A33: BAHRAIN | K33: Nevada (NV)
A34: BANGLADESH | K34: Maine (ME)
A35: BARBADOS | K35: Montana (MT)
A36: BELARUS | K36: Mississippi (MS)
A37: BELGIUM | K37: New Mexico (NM)
A38: BELIZE | K38: Lowa (IA)
A39: BENIN | K39: Rhode Island (RI)
A40: BERMUDA | K40: Kansas (KS)
...
